Workbook

Sheet Dashboard
A1: Drink Awareness App — Feature Backlog Dashboard
A2: Purpose: Track all MVP and future features with priority, effort, value and status. Updated 18 June 2026 with research findings.
A4: Total Items | C4: MVP Items | E4: Must Have | G4: Done | I4: Not Started
A5: =COUNTA('Feature Backlog'!A3:A200) -> 51 | C5: =COUNTIF('Feature Backlog'!E3:E200,"MVP") -> 42 | E5: =COUNTIF('Feature Backlog'!F3:F200,"Must") -> 29 | G5: =COUNTIF('Feature Backlog'!H3:H200,"Done") -> 0 | I5: =COUNTIF('Feature Backlog'!H3:H200,"Not Started") -> 50
A7: ID | B7: Epic | C7: Feature / Task | D7: MoSCoW | E7: Phase | F7: Priority Score | G7: Added
A8: DAA-047 | B8: Drink Logging | C8: Quick-select preset drinks on Log Drink screen | D8: Must | E8: Core feature build | F8: 14 | G8: Research 18 Jun 2026
A9: DAA-048 | B9: Drink Logging | C9: Revise required fields: drink name and time only | D9: Must | E9: Core feature build | F9: 14 | G9: Research 18 Jun 2026
A10: DAA-049 | B10: AI Insights | C10: Every insight must show what data it is based on | D10: Must | E10: Core feature build | F10: 14 | G10: Research 18 Jun 2026
A11: DAA-050 | B11: App Foundation | C11: Local-first, no account required on first launch | D11: Must | E11: Core feature build | F11: 13 | G11: Research 18 Jun 2026
A12: DAA-005 | B12: App Foundation | C12: Add non-medical disclaimer | D12: Must | E12: Core feature build | G12: Original
A13: DAA-018 | B13: Drink Logging | C13: Manual custom drink entry | D13: Must | E13: Core feature build | G13: Original
A14: DAA-023 | B14: Summaries | C14: Build daily summary screen | D14: Must | E14: Core feature build | G14: Original
A15: DAA-024 | B15: Summaries | C15: Build weekly summary screen | D15: Must | E15: Core feature build | G15: Original
A16: DAA-028 | B16: AI Insights | C16: Generate/display basic insight | D16: Must | E16: Core feature build | G16: Original

Sheet Feature Backlog
A1: Feature Backlog — 50 items (42 MVP, 8 Future) — Updated 18 June 2026
A3: ID | B3: Epic | C3: Feature / Task | D3: User Need | E3: MVP Status | F3: MoSCoW | G3: Phase | H3: Status | I3: Effort (1-5) | J3: Value (1-5) | K3: Risk (1-5) | L3: Priority Score | M3: Dependencies | N3: Acceptance Criteria | O3: Notes
A4: DAA-001 | B4: App Foundation | C4: Confirm technical stack and architecture | D4: A maintainable app foundation is needed before development begins. | E4: MVP | F4: Must | G4: Technical setup | H4: Not Started | I4: 2 | J4: 5 | K4: 2 | L4: =J4-I4-K4+10 -> 11 | M4: Product brief, MVP scope | N4: Architecture and core technologies are documented and agreed. | O4: Keep cross-platform iOS/Android goal in mind.
A5: DAA-002 | B5: App Foundation | C5: Create mobile app project structure | D5: Developers need a clean starting point for implementation. | E5: MVP | F5: Must | G5: Technical setup | H5: Not Started | I5: 2 | J5: 5 | K5: 2 | L5: =J5-I5-K5+10 -> 11 | M5: DAA-001 | N5: Project builds successfully and includes organised folders/modules.
A6: DAA-003 | B6: App Foundation | C6: Implement core navigation | D6: Users need to move between venues, logging, summaries and insights. | E6: MVP | F6: Must | G6: Core feature build | H6: Not Started | I6: 3 | J6: 5 | K6: 2 | L6: =J6-I6-K6+10 -> 10 | M6: DAA-002 | N6: Main navigation works across all MVP screens.
A7: DAA-004 | B7: App Foundation | C7: Add age 18+ positioning/onboarding notice | D7: Users should understand the app is for adults only. | E7: MVP | F7: Should | G7: Core feature build | H7: Not Started | I7: 1 | J7: 4 | K7: 2 | L7: =J7-I7-K7+10 -> 11 | M7: DAA-003 | N7: App clearly states it is intended for adults aged 18+. | O7: Responsible design requirement.
A8: DAA-005 | B8: App Foundation | C8: Add non-medical disclaimer | D8: Users need clear messaging that the app is not medical advice. | E8: MVP | F8: Must | G8: Core feature build | H8: Not Started | I8: 1 | J8: 5 | K8: 2 | L8: =J8-I8-K8+10 -> 12 | M8: DAA-003 | N8: Disclaimer is visible in onboarding, settings or relevant insight areas.
A9: DAA-006 | B9: Venue Discovery | C9: Create sample venue data model | D9: The app needs venue data for discovery and details screens. | E9: MVP | F9: Must | G9: Technical setup | H9: Not Started | I9: 2 | J9: 5 | K9: 2 | L9: =J9-I9-K9+10 -> 11 | M9: DAA-001 | N9: Venue data model supports name, location, description and venue type. | O9: Sample data acceptable for MVP.
A10: DAA-007 | B10: Venue Discovery | C10: Build venue list screen | D10: Users need a simple way to browse example venues. | E10: MVP | F10: Must | G10: Core feature build | H10: Not Started | I10: 3 | J10: 5 | K10: 2 | L10: =J10-I10-K10+10 -> 10 | M10: DAA-006 | N10: Users can view a list of venues with key details.
A11: DAA-008 | B11: Venue Discovery | C11: Build venue search | D11: Users need to quickly find venues by name or category. | E11: MVP | F11: Should | G11: Core feature build | H11: Not Started | I11: 2 | J11: 4 | K11: 2 | L11: =J11-I11-K11+10 -> 10 | M11: DAA-007 | N11: Users can search/filter venue list using simple text input.
A12: DAA-009 | B12: Venue Discovery | C12: Add map/list venue discovery view | D12: Users may expect a map-based discovery experience. | E12: MVP | F12: Must | G12: Core feature build | H12: Not Started | I12: 4 | J12: 5 | K12: 3 | L12: =J12-I12-K12+10 -> 8 | M12: DAA-006 | N12: Users can browse venues using a map and/or list interface. | O12: Map implementation can be simplified if needed.
A13: DAA-010 | B13: Venue Discovery | C13: Add basic venue filtering | D13: Users may want to filter venue types or distance. | E13: MVP | F13: Could | G13: Polish/testing/iteration | H13: Not Started | I13: 2 | J13: 3 | K13: 2 | L13: =J13-I13-K13+10 -> 9 | M13: DAA-007 | N13: Users can apply at least one simple filter to venue results. | O13: Could be moved post-MVP.
A14: DAA-011 | B14: Venue Details | C14: Build venue details screen | D14: Users need more context before logging drinks at a venue. | E14: MVP | F14: Must | G14: Core feature build | H14: Not Started | I14: 3 | J14: 5 | K14: 2 | L14: =J14-I14-K14+10 -> 10 | M14: DAA-006, DAA-007 | N14: Users can open a venue and view name, location, description and drinks.
A15: DAA-012 | B15: Drink Menus | C15: Create drink menu data model | D15: The app needs drink data for menus and quick logging. | E15: MVP | F15: Must | G15: Technical setup | H15: Not Started | I15: 2 | J15: 5 | K15: 2 | L15: =J15-I15-K15+10 -> 11 | M15: DAA-001 | N15: Drink menu data supports name, category, size, ABV and price.
A16: DAA-013 | B16: Drink Menus | C16: Build drink menu screen | D16: Users need to view drink options and prices. | E16: MVP | F16: Must | G16: Core feature build | H16: Not Started | I16: 3 | J16: 5 | K16: 2 | L16: =J16-I16-K16+10 -> 10 | M16: DAA-011, DAA-012 | N16: Users can view example drink menu items for a venue.
A17: DAA-014 | B17: Drink Menus | C17: Show drink detail information | D17: Users need useful details before logging a drink. | E17: MVP | F17: Should | G17: Core feature build | H17: Not Started | I17: 2 | J17: 4 | K17: 2 | L17: =J17-I17-K17+10 -> 10 | M17: DAA-013 | N17: Drink item shows name, type, size, ABV and price where available.
A18: DAA-015 | B18: Drink Menus | C18: Display prices and ABV clearly | D18: Users need to understand cost and alcohol strength. | E18: MVP | F18: Must | G18: Core feature build | H18: Not Started | I18: 1 | J18: 5 | K18: 2 | L18: =J18-I18-K18+10 -> 12 | M18: DAA-013 | N18: Price and ABV are clearly visible for sample drinks.
A19: DAA-016 | B19: Drink Logging | C19: Create drink log data model | D19: The app needs stored log entries to calculate summaries. | E19: MVP | F19: Must | G19: Technical setup | H19: Not Started | I19: 2 | J19: 5 | K19: 2 | L19: =J19-I19-K19+10 -> 11 | M19: DAA-001 | N19: Drink log data supports drink details, date/time and venue.
A20: DAA-017 | B20: Drink Logging | C20: Quick log from menu item | D20: Users need fast logging during social outings. | E20: MVP | F20: Must | G20: Core feature build | H20: Not Started | I20: 3 | J20: 5 | K20: 3 | L20: =J20-I20-K20+10 -> 9 | M20: DAA-013, DAA-016 | N20: Users can log a drink directly from a menu item.
A21: DAA-018 | B21: Drink Logging | C21: Manual custom drink entry | D21: Users need to log drinks that are not in a menu. | E21: MVP | F21: Must | G21: Core feature build | H21: Not Started | I21: 3 | J21: 5 | K21: 3 | L21: =J21-I21-K21+10 -> 9 | M21: DAA-016 | N21: Users can manually enter drink name, type, size, ABV and price. | O21: See DAA-048 for revised required fields from research.
A22: DAA-019 | B22: Drink Logging | C22: Calculate UK alcohol units | D22: Users need awareness of alcohol quantity, not just drink count. | E22: MVP | F22: Must | G22: Core feature build | H22: Not Started | I22: 2 | J22: 5 | K22: 2 | L22: =J22-I22-K22+10 -> 11 | M22: DAA-016 | N22: App calculates units from volume and ABV using a consistent formula. | O22: Useful portfolio feature.
A23: DAA-020 | B23: Drink Logging | C23: Log optional drink price/spend | D23: Budget-conscious users need spending visibility. | E23: MVP | F23: Should | G23: Core feature build | H23: Not Started | I23: 2 | J23: 4 | K23: 2 | L23: =J23-I23-K23+10 -> 10 | M23: DAA-016 | N23: Users can add or confirm a drink price when logging.
A24: DAA-021 | B24: Drink Logging | C24: Edit or delete logged drink | D24: Users need to fix mistakes in their logs. | E24: MVP | F24: Should | G24: Polish/testing/iteration | H24: Not Started | I24: 2 | J24: 4 | K24: 2 | L24: =J24-I24-K24+10 -> 10 | M24: DAA-016 | N24: Users can edit or delete a logged drink entry.
A25: DAA-022 | B25: Drink Logging | C25: Add helpful empty states | D25: Users need clear guidance when no drinks are logged. | E25: MVP | F25: Should | G25: Polish/testing/iteration | H25: Not Started | I25: 1 | J25: 3 | K25: 1 | L25: =J25-I25-K25+10 -> 11 | M25: DAA-023, DAA-024 | N25: Empty summary/log screens explain what to do next.
A26: DAA-023 | B26: Summaries | C26: Build daily summary screen | D26: Users need short-term awareness of drinks logged today. | E26: MVP | F26: Must | G26: Core feature build | H26: Not Started | I26: 3 | J26: 5 | K26: 2 | L26: =J26-I26-K26+10 -> 10 | M26: DAA-016, DAA-019 | N26: Daily summary shows today's drinks, units and optional spending.
A27: DAA-024 | B27: Summaries | C27: Build weekly summary screen | D27: Users need pattern awareness across multiple days. | E27: MVP | F27: Must | G27: Core feature build | H27: Not Started | I27: 3 | J27: 5 | K27: 2 | L27: =J27-I27-K27+10 -> 10 | M27: DAA-016, DAA-019 | N27: Weekly summary shows basic totals and trends for the current week.
A28: DAA-025 | B28: Summaries | C28: Add basic charts/visual summaries | D28: Users may understand patterns better visually. | E28: MVP | F28: Should | G28: Polish/testing/iteration | H28: Not Started | I28: 3 | J28: 4 | K28: 2 | L28: =J28-I28-K28+10 -> 9 | M28: DAA-023, DAA-024 | N28: Daily/weekly summaries include a simple chart or visual indicator.
A29: DAA-026 | B29: Summaries | C29: Add spending breakdown | D29: Budget-conscious users need visibility of drink spending. | E29: MVP | F29: Should | G29: Polish/testing/iteration | H29: Not Started | I29: 2 | J29: 4 | K29: 2 | L29: =J29-I29-K29+10 -> 10 | M29: DAA-020, DAA-023 | N29: Summary can show estimated spending where price is available.
A30: DAA-027 | B30: AI Insights | C30: Define AI insight rules/prompts | D30: The app needs a safe basis for generated feedback. | E30: MVP | F30: Must | G30: Core feature build | H30: Not Started | I30: 3 | J30: 5 | K30: 3 | L30: =J30-I30-K30+10 -> 9 | M30: Research findings | N30: Insight logic or prompts are documented and responsible.
A31: DAA-028 | B31: AI Insights | C31: Generate/display basic insight | D31: Users need personalised awareness feedback. | E31: MVP | F31: Must | G31: Core feature build | H31: Not Started | I31: 3 | J31: 5 | K31: 3 | L31: =J31-I31-K31+10 -> 9 | M31: DAA-023, DAA-024, DAA-027 | N31: App displays at least one useful insight based on logged data. | O31: Can start with rule-based insight if API not ready.
A32: DAA-029 | B32: AI Insights | C32: Add insight safety wording | D32: Users need feedback that is supportive and non-medical. | E32: MVP | F32: Must | G32: Core feature build | H32: Not Started | I32: 1 | J32: 5 | K32: 2 | L32: =J32-I32-K32+10 -> 12 | M32: DAA-028 | N32: Insights avoid diagnosis, shame and encouragement of excessive drinking.
A33: DAA-030 | B33: AI Insights | C33: Add insight feedback controls | D33: Users may want to dismiss or rate insights. | E33: MVP | F33: Could | G33: Polish/testing/iteration | H33: Not Started | I33: 2 | J33: 3 | K33: 2 | L33: =J33-I33-K33+10 -> 9 | M33: DAA-028 | N33: Users can dismiss or provide simple feedback on an insight. | O33: Could be future if time is tight.
A34: DAA-031 | B34: Privacy & Settings | C34: Store logged data reliably | D34: Users need their logged drinks to persist between sessions. | E34: MVP | F34: Must | G34: Technical setup | H34: Not Started | I34: 3 | J34: 5 | K34: 3 | L34: =J34-I34-K34+10 -> 9 | M34: DAA-016 | N34: Drink logs persist locally or through chosen storage approach.
A35: DAA-032 | B35: Privacy & Settings | C35: Allow data deletion | D35: Users should have control over their personal app data. | E35: MVP | F35: Should | G35: Polish/testing/iteration | H35: Not Started | I35: 2 | J35: 4 | K35: 2 | L35: =J35-I35-K35+10 -> 10 | M35: DAA-031 | N35: Users can delete logs or reset app data.
A36: DAA-033 | B36: Privacy & Settings | C36: Create basic settings screen | D36: Users need access to disclaimers and simple preferences. | E36: MVP | F36: Should | G36: Polish/testing/iteration | H36: Not Started | I36: 2 | J36: 3 | K36: 2 | L36: =J36-I36-K36+10 -> 9 | M36: DAA-003 | N36: Settings screen includes disclaimer and optional preferences.
A37: DAA-034 | B37: Testing | C37: Test alcohol unit calculation | D37: The app must calculate summaries correctly. | E37: MVP | F37: Must | G37: Polish/testing/iteration | H37: Not Started | I37: 2 | J37: 5 | K37: 2 | L37: =J37-I37-K37+10 -> 11 | M37: DAA-019 | N37: Unit calculation tests pass for multiple example drinks.
A38: DAA-035 | B38: Testing | C38: Conduct small usability test | D38: The app needs validation that users understand the flow. | E38: MVP | F38: Should | G38: Polish/testing/iteration | H38: Not Started | I38: 3 | J38: 4 | K38: 2 | L38: =J38-I38-K38+10 -> 9 | M38: MVP prototype | N38: At least a small number of users test the main flow and provide feedback.
A39: DAA-036 | B39: Testing | C39: Bug fixing and UI polish | D39: The MVP needs to be stable and presentable. | E39: MVP | F39: Must | G39: Polish/testing/iteration | H39: Not Started | I39: 4 | J39: 5 | K39: 3 | L39: =J39-I39-K39+10 -> 8 | M39: Core feature build | N39: Critical bugs are fixed and key screens look portfolio-ready.
A40: DAA-037 | B40: Deployment | C40: Create deployment checklist | D40: Release prep needs to be tracked before portfolio launch. | E40: MVP | F40: Must | G40: Deployment prep | H40: Not Started | I40: 2 | J40: 4 | K40: 2 | L40: =J40-I40-K40+10 -> 10 | M40: DAA-036 | N40: Checklist covers build, testing, screenshots, privacy notes and release tasks.
A41: DAA-038 | B41: Deployment | C41: Prepare portfolio README/screenshots | D41: The project needs to demonstrate value to viewers. | E41: MVP | F41: Must | G41: MVP deployment / portfolio-ready release | H41: Not Started | I41: 2 | J41: 5 | K41: 2 | L41: =J41-I41-K41+10 -> 11 | M41: DAA-036 | N41: GitHub README includes overview, screenshots, features and setup notes.
...

Sheet User Stories
A1: User Stories — Updated 18 June 2026
A2: Story ID | B2: Epic | C2: User Story | D2: Acceptance Criteria | E2: Linked Backlog IDs | F2: Priority
A3: US-001 | B3: Venue Discovery | C3: As a social drinker, I want to browse nearby/example venues so that I can choose where I may log drinks. | D3: Venue list or map is visible and each venue can be opened. | E3: DAA-007, DAA-009, DAA-011 | F3: Must
A4: US-002 | B4: Drink Menus | C4: As a user, I want to view drink names, ABV and prices so that I can make more informed choices. | D4: Menu shows sample drinks with useful details. | E4: DAA-012, DAA-013, DAA-015 | F4: Must
A5: US-003 | B5: Drink Logging | C5: As a user, I want to log a drink quickly so that I can track consumption during a social outing. | D5: User can log from a menu item or manual entry form. | E5: DAA-017, DAA-018 | F5: Must
A6: US-004 | B6: Drink Logging | C6: As a user, I want the app to estimate alcohol units so that I can understand more than just drink count. | D6: Logged drinks calculate units consistently from size and ABV. | E6: DAA-019 | F6: Must
A7: US-005 | B7: Summaries | C7: As a user, I want a daily summary so that I can see what I have logged today. | D7: Today's drinks, units and optional spending are displayed. | E7: DAA-023 | F7: Must
A8: US-006 | B8: Summaries | C8: As a user, I want a weekly summary so that I can spot patterns across several days. | D8: Weekly totals and basic visual summary are displayed. | E8: DAA-024, DAA-025 | F8: Must
A9: US-007 | B9: AI Insights | C9: As a user, I want supportive insights so that I can reflect on my drinking habits without feeling judged. | D9: At least one insight is shown and uses non-medical wording. | E9: DAA-027, DAA-028, DAA-029 | F9: Must
A10: US-008 | B10: Privacy & Settings | C10: As a user, I want privacy and control so that I feel safe using the app. | D10: App avoids unnecessary data collection and allows deletion/reset. | E10: DAA-031, DAA-032 | F10: Should
A11: US-009 | B11: Portfolio | C11: As a portfolio viewer, I want to understand the project quickly so that I can see the product value. | D11: README includes purpose, screenshots, features and setup information. | E11: DAA-038 | F11: Must
A12: US-010 | B12: Drink Logging | C12: As a user, I want to select a drink from a quick-select list so that I can log it in a few seconds. | D12: Preset list visible on Log Drink screen. Tapping a preset logs it with minimal additional input. | E12: DAA-047 | F12: Must
A13: US-011 | B13: Drink Logging | C13: As a user, I want drink name and time to be the only required fields so that logging never feels like a chore. | D13: Log Drink form completes successfully with only name and time. All other fields shown as optional. | E13: DAA-048 | F13: Must
A14: US-012 | B14: AI Insights | C14: As a user, I want every AI insight to tell me what data it is based on so that I can decide whether to trust it. | D14: Every displayed insight includes a visible note explaining its data basis. | E14: DAA-049 | F14: Must

Sheet Release Plan
A1: Release Plan — Updated 18 June 2026
A2: Phase | B2: Date Range | C2: Main Focus | D2: Key Outputs | E2: Related Backlog Items | F2: Status
A3: Research and validation | B3: 18 May – 31 May 2026 | C3: Validate problem, users, competitors and assumptions. | D3: Research plan, interview questions, competitor analysis, survey findings. | E3: DAA-035, research inputs | F3: Done
A4: Planning and backlog | B4: 1 Jun – 18 Jun 2026 | C4: Turn project scope into tasks and prioritised build plan. | D4: MVP scope, feature backlog updated with research findings. | E4: All backlog items | F4: Done
A5: UX/UI design | B5: 15 Jun – 28 Jun 2026 | C5: Design core app screens and user flows. | D5: Wireframes, navigation flow, screen designs. | E5: DAA-003, DAA-007, DAA-011, DAA-013, DAA-018, DAA-023, DAA-024, DAA-028, DAA-047 | F5: In Progress
A6: Technical setup | B6: 29 Jun – 12 Jul 2026 | C6: Set up app structure, data models and core architecture. | D6: Project setup, data models, storage approach. | E6: DAA-001, DAA-002, DAA-006, DAA-012, DAA-016, DAA-031 | F6: Not Started
A7: Core feature build | B7: 13 Jul – 23 Aug 2026 | C7: Build MVP screens and core functionality. | D7: Venue discovery, logging, summaries, insights, presets. | E7: DAA-003 to DAA-030, DAA-047 to DAA-050 | F7: Not Started
A8: Polish, testing, iteration | B8: 24 Aug – 20 Sep 2026 | C8: Improve usability, fix bugs and validate with users. | D8: Charts, edit/delete, testing, bug fixes. | E8: DAA-010, DAA-021 to DAA-026, DAA-030, DAA-032 to DAA-036 | F8: Not Started
A9: Deployment prep | B9: 21 Sep – 4 Oct 2026 | C9: Prepare app and repo for release/demo. | D9: Checklist, final testing, release preparation. | E9: DAA-037 | F9: Not Started
A10: MVP deployment / portfolio release | B10: 5 Oct – 18 Oct 2026 | C10: Create final portfolio-ready release. | D10: README, screenshots, release notes. | E10: DAA-038 | F10: Not Started
A11: Post-MVP | B11: After 18 Oct 2026 | C11: Evaluate future ideas after first version is validated. | D11: Future backlog review. | E11: DAA-039 to DAA-046 | F11: Deferred

Sheet Prioritisation Guide
A1: Feature Backlog — Prioritisation Guide
A2: Field | B2: Meaning | C2: How to Use | D2: Example
A3: MVP Status | B3: Whether the item belongs in the first build or future backlog. | C3: Use MVP for first version work; Future for post-MVP ideas. | D3: MVP
A4: MoSCoW | B4: Must, Should, Could, Won’t for MVP prioritisation. | C4: Must items are required for MVP completion. | D4: Must
A5: Effort (1-5) | B5: Estimated work required. | C5: 1 is small/easy; 5 is large/complex. | D5: 3
A6: Value (1-5) | B6: Expected value to users/project. | C6: 1 is low value; 5 is high value. | D6: 5
A7: Risk (1-5) | B7: Uncertainty, technical complexity or responsible design risk. | C7: 1 is low risk; 5 is high risk. | D7: 2
A8: Priority Score | B8: Formula: Value - Effort - Risk + 10. | C8: Higher score = stronger candidate for earlier delivery. | D8: Calculated
A9: Status | B9: Current progress on this item. | C9: Update throughout the build phase. | D9: Not Started
A10: Dependencies | B10: Other items needed before this one can start. | C10: Use IDs so dependencies remain clear. | D10: DAA-016

Sheet Lists
A1: MVP Status | B1: MoSCoW | C1: Phase | D1: Status
A2: MVP | B2: Must | C2: Research and validation | D2: Not Started
A3: Future | B3: Should | C3: Planning and backlog | D3: In Progress
B4: Could | C4: UX/UI design | D4: Blocked
B5: Won't | C5: Technical setup | D5: Done
C6: Core feature build | D6: Deferred
C7: Polish/testing/iteration
C8: Deployment prep
C9: MVP deployment / portfolio-ready release
C10: Post-MVP
